ERROR 2025-08-11 01:30:46,633 error_handler 8324 19576 API Error: name 'serializers' is not defined
Traceback (most recent call last):
  File "C:\Python312\Lib\site-packages\django\db\backends\utils.py", line 89, in _execute
    return self.cursor.execute(sql, params)
           ^^^^^^^^^^^^^^^^^^^^^^^^^^^^^^^^
  File "C:\Python312\Lib\site-packages\django\db\backends\sqlite3\base.py", line 328, in execute
    return super().execute(query, params)
           ^^^^^^^^^^^^^^^^^^^^^^^^^^^^^^
sqlite3.OperationalError: no such table: accounts_user

The above exception was the direct cause of the following exception:

Traceback (most recent call last):
  File "C:\Users\reube\CareerOpen-App\careeropen-backend\accounts\views.py", line 657, in create
    logger.info(f"Is valid: {serializer.is_valid()}")
                             ^^^^^^^^^^^^^^^^^^^^^
  File "C:\Python312\Lib\site-packages\rest_framework\serializers.py", line 225, in is_valid
    self._validated_data = self.run_validation(self.initial_data)
                           ^^^^^^^^^^^^^^^^^^^^^^^^^^^^^^^^^^^^^^
  File "C:\Python312\Lib\site-packages\rest_framework\serializers.py", line 444, in run_validation
    value = self.to_internal_value(data)
            ^^^^^^^^^^^^^^^^^^^^^^^^^^^^
  File "C:\Python312\Lib\site-packages\rest_framework\serializers.py", line 501, in to_internal_value
    validated_value = field.run_validation(primitive_value)
                      ^^^^^^^^^^^^^^^^^^^^^^^^^^^^^^^^^^^^^
  File "C:\Python312\Lib\site-packages\rest_framework\fields.py", line 757, in run_validation
    return super().run_validation(data)
           ^^^^^^^^^^^^^^^^^^^^^^^^^^^^
  File "C:\Python312\Lib\site-packages\rest_framework\fields.py", line 539, in run_validation
    self.run_validators(value)
  File "C:\Python312\Lib\site-packages\rest_framework\fields.py", line 551, in run_validators
    validator(value, self)
  File "C:\Python312\Lib\site-packages\rest_framework\validators.py", line 86, in __call__
    if qs_exists(queryset):
       ^^^^^^^^^^^^^^^^^^^
  File "C:\Python312\Lib\site-packages\rest_framework\validators.py", line 23, in qs_exists
    return queryset.exists()
           ^^^^^^^^^^^^^^^^^
  File "C:\Python312\Lib\site-packages\django\db\models\query.py", line 1241, in exists
    return self.query.has_results(using=self.db)
           ^^^^^^^^^^^^^^^^^^^^^^^^^^^^^^^^^^^^^
  File "C:\Python312\Lib\site-packages\django\db\models\sql\query.py", line 598, in has_results
    return compiler.has_results()
           ^^^^^^^^^^^^^^^^^^^^^^
  File "C:\Python312\Lib\site-packages\django\db\models\sql\compiler.py", line 1530, in has_results
    return bool(self.execute_sql(SINGLE))
                ^^^^^^^^^^^^^^^^^^^^^^^^
  File "C:\Python312\Lib\site-packages\django\db\models\sql\compiler.py", line 1562, in execute_sql
    cursor.execute(sql, params)
  File "C:\Python312\Lib\site-packages\django\db\backends\utils.py", line 102, in execute
    return super().execute(sql, params)
           ^^^^^^^^^^^^^^^^^^^^^^^^^^^^
  File "C:\Python312\Lib\site-packages\django\db\backends\utils.py", line 67, in execute
    return self._execute_with_wrappers(
           ^^^^^^^^^^^^^^^^^^^^^^^^^^^^
  File "C:\Python312\Lib\site-packages\django\db\backends\utils.py", line 80, in _execute_with_wrappers
    return executor(sql, params, many, context)
           ^^^^^^^^^^^^^^^^^^^^^^^^^^^^^^^^^^^^
  File "C:\Python312\Lib\site-packages\django\db\backends\utils.py", line 84, in _execute
    with self.db.wrap_database_errors:
  File "C:\Python312\Lib\site-packages\django\db\utils.py", line 91, in __exit__
    raise dj_exc_value.with_traceback(traceback) from exc_value
  File "C:\Python312\Lib\site-packages\django\db\backends\utils.py", line 89, in _execute
    return self.cursor.execute(sql, params)
           ^^^^^^^^^^^^^^^^^^^^^^^^^^^^^^^^
  File "C:\Python312\Lib\site-packages\django\db\backends\sqlite3\base.py", line 328, in execute
    return super().execute(query, params)
           ^^^^^^^^^^^^^^^^^^^^^^^^^^^^^^
django.db.utils.OperationalError: no such table: accounts_user

During handling of the above exception, another exception occurred:

Traceback (most recent call last):
  File "C:\Python312\Lib\site-packages\rest_framework\views.py", line 512, in dispatch
    response = handler(request, *args, **kwargs)
               ^^^^^^^^^^^^^^^^^^^^^^^^^^^^^^^^^
  File "C:\Python312\Lib\site-packages\rest_framework\generics.py", line 194, in post
    return self.create(request, *args, **kwargs)
           ^^^^^^^^^^^^^^^^^^^^^^^^^^^^^^^^^^^^^
  File "C:\Users\reube\CareerOpen-App\careeropen-backend\accounts\views.py", line 741, in create
    except serializers.ValidationError as e:
           ^^^^^^^^^^^
NameError: name 'serializers' is not defined. Did you mean: 'serializer'?
ERROR 2025-08-11 01:30:47,934 log 8324 19576 Internal Server Error: /api/auth/register/
ERROR 2025-08-11 01:30:48,733 basehttp 8324 19576 "POST /api/auth/register/ HTTP/1.1" 500 93
ERROR 2025-08-11 01:30:59,524 error_handler 8324 17372 API Error: name 'serializers' is not defined
Traceback (most recent call last):
  File "C:\Python312\Lib\site-packages\django\db\backends\utils.py", line 89, in _execute
    return self.cursor.execute(sql, params)
           ^^^^^^^^^^^^^^^^^^^^^^^^^^^^^^^^
  File "C:\Python312\Lib\site-packages\django\db\backends\sqlite3\base.py", line 328, in execute
    return super().execute(query, params)
           ^^^^^^^^^^^^^^^^^^^^^^^^^^^^^^
sqlite3.OperationalError: no such table: accounts_user

The above exception was the direct cause of the following exception:

Traceback (most recent call last):
  File "C:\Users\reube\CareerOpen-App\careeropen-backend\accounts\views.py", line 657, in create
    logger.info(f"Is valid: {serializer.is_valid()}")
                             ^^^^^^^^^^^^^^^^^^^^^
  File "C:\Python312\Lib\site-packages\rest_framework\serializers.py", line 225, in is_valid
    self._validated_data = self.run_validation(self.initial_data)
                           ^^^^^^^^^^^^^^^^^^^^^^^^^^^^^^^^^^^^^^
  File "C:\Python312\Lib\site-packages\rest_framework\serializers.py", line 444, in run_validation
    value = self.to_internal_value(data)
            ^^^^^^^^^^^^^^^^^^^^^^^^^^^^
  File "C:\Python312\Lib\site-packages\rest_framework\serializers.py", line 501, in to_internal_value
    validated_value = field.run_validation(primitive_value)
                      ^^^^^^^^^^^^^^^^^^^^^^^^^^^^^^^^^^^^^
  File "C:\Python312\Lib\site-packages\rest_framework\fields.py", line 757, in run_validation
    return super().run_validation(data)
           ^^^^^^^^^^^^^^^^^^^^^^^^^^^^
  File "C:\Python312\Lib\site-packages\rest_framework\fields.py", line 539, in run_validation
    self.run_validators(value)
  File "C:\Python312\Lib\site-packages\rest_framework\fields.py", line 551, in run_validators
    validator(value, self)
  File "C:\Python312\Lib\site-packages\rest_framework\validators.py", line 86, in __call__
    if qs_exists(queryset):
       ^^^^^^^^^^^^^^^^^^^
  File "C:\Python312\Lib\site-packages\rest_framework\validators.py", line 23, in qs_exists
    return queryset.exists()
           ^^^^^^^^^^^^^^^^^
  File "C:\Python312\Lib\site-packages\django\db\models\query.py", line 1241, in exists
    return self.query.has_results(using=self.db)
           ^^^^^^^^^^^^^^^^^^^^^^^^^^^^^^^^^^^^^
  File "C:\Python312\Lib\site-packages\django\db\models\sql\query.py", line 598, in has_results
    return compiler.has_results()
           ^^^^^^^^^^^^^^^^^^^^^^
  File "C:\Python312\Lib\site-packages\django\db\models\sql\compiler.py", line 1530, in has_results
    return bool(self.execute_sql(SINGLE))
                ^^^^^^^^^^^^^^^^^^^^^^^^
  File "C:\Python312\Lib\site-packages\django\db\models\sql\compiler.py", line 1562, in execute_sql
    cursor.execute(sql, params)
  File "C:\Python312\Lib\site-packages\django\db\backends\utils.py", line 102, in execute
    return super().execute(sql, params)
           ^^^^^^^^^^^^^^^^^^^^^^^^^^^^
  File "C:\Python312\Lib\site-packages\django\db\backends\utils.py", line 67, in execute
    return self._execute_with_wrappers(
           ^^^^^^^^^^^^^^^^^^^^^^^^^^^^
  File "C:\Python312\Lib\site-packages\django\db\backends\utils.py", line 80, in _execute_with_wrappers
    return executor(sql, params, many, context)
           ^^^^^^^^^^^^^^^^^^^^^^^^^^^^^^^^^^^^
  File "C:\Python312\Lib\site-packages\django\db\backends\utils.py", line 84, in _execute
    with self.db.wrap_database_errors:
  File "C:\Python312\Lib\site-packages\django\db\utils.py", line 91, in __exit__
    raise dj_exc_value.with_traceback(traceback) from exc_value
  File "C:\Python312\Lib\site-packages\django\db\backends\utils.py", line 89, in _execute
    return self.cursor.execute(sql, params)
           ^^^^^^^^^^^^^^^^^^^^^^^^^^^^^^^^
  File "C:\Python312\Lib\site-packages\django\db\backends\sqlite3\base.py", line 328, in execute
    return super().execute(query, params)
           ^^^^^^^^^^^^^^^^^^^^^^^^^^^^^^
django.db.utils.OperationalError: no such table: accounts_user

During handling of the above exception, another exception occurred:

Traceback (most recent call last):
  File "C:\Python312\Lib\site-packages\rest_framework\views.py", line 512, in dispatch
    response = handler(request, *args, **kwargs)
               ^^^^^^^^^^^^^^^^^^^^^^^^^^^^^^^^^
  File "C:\Python312\Lib\site-packages\rest_framework\generics.py", line 194, in post
    return self.create(request, *args, **kwargs)
           ^^^^^^^^^^^^^^^^^^^^^^^^^^^^^^^^^^^^^
  File "C:\Users\reube\CareerOpen-App\careeropen-backend\accounts\views.py", line 741, in create
    except serializers.ValidationError as e:
           ^^^^^^^^^^^
NameError: name 'serializers' is not defined. Did you mean: 'serializer'?
ERROR 2025-08-11 01:30:59,560 log 8324 17372 Internal Server Error: /api/auth/register/
ERROR 2025-08-11 01:30:59,633 basehttp 8324 17372 "POST /api/auth/register/ HTTP/1.1" 500 93
ERROR 2025-08-11 01:31:40,534 error_handler 8324 19028 API Error: name 'serializers' is not defined
Traceback (most recent call last):
  File "C:\Python312\Lib\site-packages\django\db\backends\utils.py", line 89, in _execute
    return self.cursor.execute(sql, params)
           ^^^^^^^^^^^^^^^^^^^^^^^^^^^^^^^^
  File "C:\Python312\Lib\site-packages\django\db\backends\sqlite3\base.py", line 328, in execute
    return super().execute(query, params)
           ^^^^^^^^^^^^^^^^^^^^^^^^^^^^^^
sqlite3.OperationalError: no such table: accounts_user

The above exception was the direct cause of the following exception:

Traceback (most recent call last):
  File "C:\Users\reube\CareerOpen-App\careeropen-backend\accounts\views.py", line 657, in create
    logger.info(f"Is valid: {serializer.is_valid()}")
                             ^^^^^^^^^^^^^^^^^^^^^
  File "C:\Python312\Lib\site-packages\rest_framework\serializers.py", line 225, in is_valid
    self._validated_data = self.run_validation(self.initial_data)
                           ^^^^^^^^^^^^^^^^^^^^^^^^^^^^^^^^^^^^^^
  File "C:\Python312\Lib\site-packages\rest_framework\serializers.py", line 444, in run_validation
    value = self.to_internal_value(data)
            ^^^^^^^^^^^^^^^^^^^^^^^^^^^^
  File "C:\Python312\Lib\site-packages\rest_framework\serializers.py", line 501, in to_internal_value
    validated_value = field.run_validation(primitive_value)
                      ^^^^^^^^^^^^^^^^^^^^^^^^^^^^^^^^^^^^^
  File "C:\Python312\Lib\site-packages\rest_framework\fields.py", line 757, in run_validation
    return super().run_validation(data)
           ^^^^^^^^^^^^^^^^^^^^^^^^^^^^
  File "C:\Python312\Lib\site-packages\rest_framework\fields.py", line 539, in run_validation
    self.run_validators(value)
  File "C:\Python312\Lib\site-packages\rest_framework\fields.py", line 551, in run_validators
    validator(value, self)
  File "C:\Python312\Lib\site-packages\rest_framework\validators.py", line 86, in __call__
    if qs_exists(queryset):
       ^^^^^^^^^^^^^^^^^^^
  File "C:\Python312\Lib\site-packages\rest_framework\validators.py", line 23, in qs_exists
    return queryset.exists()
           ^^^^^^^^^^^^^^^^^
  File "C:\Python312\Lib\site-packages\django\db\models\query.py", line 1241, in exists
    return self.query.has_results(using=self.db)
           ^^^^^^^^^^^^^^^^^^^^^^^^^^^^^^^^^^^^^
  File "C:\Python312\Lib\site-packages\django\db\models\sql\query.py", line 598, in has_results
    return compiler.has_results()
           ^^^^^^^^^^^^^^^^^^^^^^
  File "C:\Python312\Lib\site-packages\django\db\models\sql\compiler.py", line 1530, in has_results
    return bool(self.execute_sql(SINGLE))
                ^^^^^^^^^^^^^^^^^^^^^^^^
  File "C:\Python312\Lib\site-packages\django\db\models\sql\compiler.py", line 1562, in execute_sql
    cursor.execute(sql, params)
  File "C:\Python312\Lib\site-packages\django\db\backends\utils.py", line 102, in execute
    return super().execute(sql, params)
           ^^^^^^^^^^^^^^^^^^^^^^^^^^^^
  File "C:\Python312\Lib\site-packages\django\db\backends\utils.py", line 67, in execute
    return self._execute_with_wrappers(
           ^^^^^^^^^^^^^^^^^^^^^^^^^^^^
  File "C:\Python312\Lib\site-packages\django\db\backends\utils.py", line 80, in _execute_with_wrappers
    return executor(sql, params, many, context)
           ^^^^^^^^^^^^^^^^^^^^^^^^^^^^^^^^^^^^
  File "C:\Python312\Lib\site-packages\django\db\backends\utils.py", line 84, in _execute
    with self.db.wrap_database_errors:
  File "C:\Python312\Lib\site-packages\django\db\utils.py", line 91, in __exit__
    raise dj_exc_value.with_traceback(traceback) from exc_value
  File "C:\Python312\Lib\site-packages\django\db\backends\utils.py", line 89, in _execute
    return self.cursor.execute(sql, params)
           ^^^^^^^^^^^^^^^^^^^^^^^^^^^^^^^^
  File "C:\Python312\Lib\site-packages\django\db\backends\sqlite3\base.py", line 328, in execute
    return super().execute(query, params)
           ^^^^^^^^^^^^^^^^^^^^^^^^^^^^^^
django.db.utils.OperationalError: no such table: accounts_user

During handling of the above exception, another exception occurred:

Traceback (most recent call last):
  File "C:\Python312\Lib\site-packages\rest_framework\views.py", line 512, in dispatch
    response = handler(request, *args, **kwargs)
               ^^^^^^^^^^^^^^^^^^^^^^^^^^^^^^^^^
  File "C:\Python312\Lib\site-packages\rest_framework\generics.py", line 194, in post
    return self.create(request, *args, **kwargs)
           ^^^^^^^^^^^^^^^^^^^^^^^^^^^^^^^^^^^^^
  File "C:\Users\reube\CareerOpen-App\careeropen-backend\accounts\views.py", line 741, in create
    except serializers.ValidationError as e:
           ^^^^^^^^^^^
NameError: name 'serializers' is not defined. Did you mean: 'serializer'?
ERROR 2025-08-11 01:31:40,549 log 8324 19028 Internal Server Error: /api/auth/register/
ERROR 2025-08-11 01:31:40,573 basehttp 8324 19028 "POST /api/auth/register/ HTTP/1.1" 500 93
ERROR 2025-08-11 01:31:47,301 error_handler 8324 19028 API Error: 'utf-8' codec can't decode byte 0x80 in position 0: invalid start byte
Traceback (most recent call last):
  File "C:\Python312\Lib\site-packages\rest_framework\views.py", line 503, in dispatch
    self.initial(request, *args, **kwargs)
  File "C:\Python312\Lib\site-packages\rest_framework\views.py", line 422, in initial
    self.check_throttles(request)
  File "C:\Python312\Lib\site-packages\rest_framework\views.py", line 365, in check_throttles
    if not throttle.allow_request(request, self):
           ^^^^^^^^^^^^^^^^^^^^^^^^^^^^^^^^^^^^^
  File "C:\Python312\Lib\site-packages\rest_framework\throttling.py", line 123, in allow_request
    self.history = self.cache.get(self.key, [])
                   ^^^^^^^^^^^^^^^^^^^^^^^^^^^^
  File "C:\Python312\Lib\site-packages\django_redis\cache.py", line 92, in get
    value = self._get(key, default, version, client)
            ^^^^^^^^^^^^^^^^^^^^^^^^^^^^^^^^^^^^^^^^
  File "C:\Python312\Lib\site-packages\django_redis\cache.py", line 29, in _decorator
    return method(self, *args, **kwargs)
           ^^^^^^^^^^^^^^^^^^^^^^^^^^^^^
  File "C:\Python312\Lib\site-packages\django_redis\cache.py", line 99, in _get
    return self.client.get(key, default=default, version=version, client=client)
           ^^^^^^^^^^^^^^^^^^^^^^^^^^^^^^^^^^^^^^^^^^^^^^^^^^^^^^^^^^^^^^^^^^^^^
  File "C:\Python312\Lib\site-packages\django_redis\client\default.py", line 298, in get
    value = client.get(key)
            ^^^^^^^^^^^^^^^
  File "C:\Python312\Lib\site-packages\redis\commands\core.py", line 1829, in get
    return self.execute_command("GET", name, keys=[name])
           ^^^^^^^^^^^^^^^^^^^^^^^^^^^^^^^^^^^^^^^^^^^^^^
  File "C:\Python312\Lib\site-packages\redis\client.py", line 623, in execute_command
    return self._execute_command(*args, **options)
           ^^^^^^^^^^^^^^^^^^^^^^^^^^^^^^^^^^^^^^^
  File "C:\Python312\Lib\site-packages\redis\client.py", line 634, in _execute_command
    return conn.retry.call_with_retry(
           ^^^^^^^^^^^^^^^^^^^^^^^^^^^
  File "C:\Python312\Lib\site-packages\redis\retry.py", line 87, in call_with_retry
    return do()
           ^^^^
  File "C:\Python312\Lib\site-packages\redis\client.py", line 635, in <lambda>
    lambda: self._send_command_parse_response(
            ^^^^^^^^^^^^^^^^^^^^^^^^^^^^^^^^^^
  File "C:\Python312\Lib\site-packages\redis\client.py", line 606, in _send_command_parse_response
    return self.parse_response(conn, command_name, **options)
           ^^^^^^^^^^^^^^^^^^^^^^^^^^^^^^^^^^^^^^^^^^^^^^^^^^
  File "C:\Python312\Lib\site-packages\redis\client.py", line 653, in parse_response
    response = connection.read_response()
               ^^^^^^^^^^^^^^^^^^^^^^^^^^
  File "C:\Python312\Lib\site-packages\fakeredis\_connection.py", line 102, in read_response
    return self._decode(response)
           ^^^^^^^^^^^^^^^^^^^^^^
  File "C:\Python312\Lib\site-packages\fakeredis\_connection.py", line 81, in _decode
    return self.encoder.decode(response)  # type: ignore
           ^^^^^^^^^^^^^^^^^^^^^^^^^^^^^
  File "C:\Python312\Lib\site-packages\redis\_parsers\encoders.py", line 43, in decode
    value = value.decode(self.encoding, self.encoding_errors)
            ^^^^^^^^^^^^^^^^^^^^^^^^^^^^^^^^^^^^^^^^^^^^^^^^^
UnicodeDecodeError: 'utf-8' codec can't decode byte 0x80 in position 0: invalid start byte
ERROR 2025-08-11 01:31:47,758 log 8324 19028 Internal Server Error: /api/auth/register/
ERROR 2025-08-11 01:31:47,848 basehttp 8324 19028 "POST /api/auth/register/ HTTP/1.1" 500 93
